<?xml version="1.0"?>
<robot name="rover">

  <!-- ================= BASE ================= -->
  <link name="base_link">
    <visual>
      <geometry>
        <box size="0.5 0.4 0.15"/>
      </geometry>
    </visual>
    <collision>
      <geometry>
        <box size="0.5 0.4 0.15"/>
      </geometry>
    </collision>
    <inertial>
      <mass value="10.0"/>
      <origin xyz="0 0 0"/>
      <inertia ixx="0.1" ixy="0.0" ixz="0.0"
               iyy="0.1" iyz="0.0"
               izz="0.1"/>
    </inertial>
  </link>

  <!-- ================= LEFT WHEEL ================= -->
  <link name="left_wheel"/>
  <joint name="left_wheel_joint" type="continuous">
    <parent link="base_link"/>
    <child link="left_wheel"/>
    <origin xyz="0 0.2 -0.075" rpy="0 1.5708 0"/>
    <axis xyz="0 0 1"/>
  </joint>

  <!-- ================= RIGHT WHEEL ================= -->
  <link name="right_wheel"/>
  <joint name="right_wheel_joint" type="continuous">
    <parent link="base_link"/>
    <child link="right_wheel"/>
    <origin xyz="0 -0.2 -0.075" rpy="0 1.5708 0"/>
    <axis xyz="0 0 1"/>
  </joint>

  <!-- ================= LIDAR ================= -->
  <link name="lidar_link"/>

  <joint name="lidar_joint" type="fixed">
    <parent link="base_link"/>
    <child link="lidar_link"/>
    <origin xyz="0.25 0 0.12" rpy="0 0 0"/>
  </joint>

  <!-- ================= GAZEBO SENSOR ================= -->
  <gazebo reference="lidar_link">
    <sensor name="lidar_sensor" type="ray">
      <always_on>true</always_on>
      <update_rate>10</update_rate>

      <ray>
        <scan>
          <horizontal>
            <samples>360</samples>
            <min_angle>-3.14159</min_angle>
            <max_angle>3.14159</max_angle>
          </horizontal>
        </scan>
        <range>
          <min>0.12</min>
          <max>10.0</max>
        </range>
      </ray>

      <!-- 🔴 THIS PLUGIN MUST LOAD -->
      <plugin name="gazebo_ros_ray_sensor" filename="libgazebo_ros_ray_sensor.so">
        <ros>
          <namespace>/</namespace>
        </ros>
        <frameName>lidar_link</frameName>
        <topicName>scan</topicName>
        <output_type>sensor_msgs/LaserScan</output_type>
      </plugin>

    </sensor>
  </gazebo>

</robot>
