<?xml version="1.0" ?>
<!-- This file was generated automatically. [2021_08_18_14_10_08] -->
<!-- [Tool url: git@github.jpl.nasa.gov:CR/rst.git, branch: dev/working, commit_hash: 47e8686b, commit_time: 2021-08-16 19:00:50 -0700] -->

<robot name="Perseverance">
    <link name="ground">
        <inertial>
        </inertial>
    </link>
    <link name="Body_Chassis">
        <inertial>
        </inertial>
        <visual name="VisGeom_CHASSIS">
        </visual>
    </link>
    <link name="Body_MHS_DebrisShield">
        <inertial>
        </inertial>
        <!-- hidden visual element
        <visual name="VisGeom_MHS_DebrisShield">
        </visual>
        -->
    </link>
    <link name="Body_Differential">
        <inertial>
        </inertial>
        <visual name="VisGeom_CenterDifferential">
        </visual>
    </link>
    <link name="Body_RockerLeft">
        <inertial>
        </inertial>
        <visual name="VisGeom_Left_Rocker">
        </visual>
    </link>
    <link name="Body_BogieLeft">
        <inertial>
        </inertial>
        <visual name="VisGeom_Left_Bogie">
        </visual>
    </link>
    <link name="Body_SteerLeftRear">
        <inertial>
        </inertial>
        <visual name="VisGeom_Steer_LeftRear">
        </visual>
    </link>
    <link name="Body_WheelLeftRear">
        <inertial>
        </inertial>
        <visual name="VisGeom_Wheel_LeftRear">
        </visual>
    </link>
    <link name="Body_WheelLeftMiddle">
        <inertial>
        </inertial>
        <visual name="VisGeom_Wheel_LeftMiddle">
        </visual>
    </link>
    <link name="Body_SteerLeftFront">
        <inertial>
        </inertial>
        <visual name="VisGeom_Steer_LeftFront">
        </visual>
    </link>
    <link name="Body_WheelLeftFront">
        <inertial>
        </inertial>
        <visual name="VisGeom_Wheel_LeftFront">
        </visual>
    </link>
    <link name="Body_RockerRight">
        <inertial>
        </inertial>
        <visual name="VisGeom_Right_Rocker">
        </visual>
    </link>
    <link name="Body_BogieRight">
        <inertial>
        </inertial>
        <visual name="VisGeom_Right_Bogie">
        </visual>
    </link>
    <link name="Body_SteerRightRear">
        <inertial>
        </inertial>
        <visual name="VisGeom_Steer_RightRear">
        </visual>
    </link>
    <link name="Body_WheelRightRear">
        <inertial>
        </inertial>
        <visual name="VisGeom_Wheel_RightRear">
        </visual>
    </link>
    <link name="Body_WheelRightMiddle">
        <inertial>
        </inertial>
        <visual name="VisGeom_Wheel_RightMiddle">
        </visual>
    </link>
    <link name="Body_SteerRightFront">
        <inertial>
        </inertial>
        <visual name="VisGeom_Steer_RightFront">
        </visual>
    </link>
    <link name="Body_WheelRightFront">
        <inertial>
        </inertial>
        <visual name="VisGeom_Wheel_RightFront">
        </visual>
    </link>
    <link name="Body_RSM_AZ">
        <inertial>
        </inertial>
        <visual name="VisGeom_RSM">
        </visual>
    </link>
    <link name="Body_RSM_EL">
        <inertial>
        </inertial>
        <visual name="VisGeom_RSM_HEAD">
        </visual>
    </link>
    <link name="Body_HGA_AZ">
        <inertial>
        </inertial>
        <visual name="VisGeom_HGA_AZ">
        </visual>
    </link>
    <link name="Body_HGA_EL">
        <inertial>
        </inertial>
        <visual name="VisGeom_HGA_EL">
        </visual>
    </link>
    <link name="Body_RA_Base">
        <inertial>
        </inertial>
    </link>
    <link name="Body_RA_Link1">
        <inertial>
        </inertial>
        <visual name="VisGeom_Arm_LINK_1">
        </visual>
    </link>
    <link name="Body_RA_Link2">
        <inertial>
        </inertial>
        <visual name="VisGeom_Arm_LINK_2">
        </visual>
    </link>
    <link name="Body_RA_Link3">
        <inertial>
        </inertial>
        <visual name="VisGeom_Arm_LINK_3">
        </visual>
    </link>
    <link name="Body_RA_Link4">
        <inertial>
        </inertial>
        <visual name="VisGeom_Arm_LINK_4">
        </visual>
    </link>
    <link name="Body_RA_Link5">
        <inertial>
        </inertial>
        <visual name="VisGeom_Arm_LINK_5">
        </visual>
    </link>
    <link name="Body_Turret">
        <inertial>
        </inertial>
        <visual name="VisGeom_Turret">
        </visual>
    </link>
    <link name="Body_CorerFeed">
        <inertial>
        </inertial>
        <!-- hidden visual element
        <visual name="VisGeom_LaunchBit">
        </visual>
        -->
        <visual name="VisGeom_AbradingBit">
        </visual>
        <!-- hidden visual element
        <visual name="VisGeom_CoringBit">
        </visual>
        -->
        <!-- hidden visual element
        <visual name="VisGeom_RegolithBit">
        </visual>
        -->
    </link>
    <link name="Body_StabilizerFar">
        <inertial>
        </inertial>
        <visual name="VisGeom_StabilizerFar">
        </visual>
    </link>
    <link name="Body_StabilizerNear">
        <inertial>
        </inertial>
        <visual name="VisGeom_StabilizerNear">
        </visual>
    </link>
    <link name="Body_WATSON_Cap">
        <inertial>
        </inertial>
        <visual name="VisGeom_WATSON_Cap">
        </visual>
    </link>
    <link name="Body_SHERLOC_Cap">
        <inertial>
        </inertial>
        <visual name="VisGeom_SHERLOC_Cap">
        </visual>
    </link>
    <link name="Frame_RNAV">
        <inertial>
        </inertial>
    </link>
    <link name="Frame_RMECH">
        <inertial>
        </inertial>
    </link>
    <link name="Frame_FHCB">
        <inertial>
        </inertial>
    </link>
    <link name="Frame_FHC1">
        <inertial>
        </inertial>
    </link>
    <link name="Frame_FHC2">
        <inertial>
        </inertial>
    </link>
    <link name="Frame_FHC3">
        <inertial>
        </inertial>
    </link>
    <link name="Frame_FHC4">
        <inertial>
        </inertial>
    </link>
    <link name="Frame_FHC1_FOV">
        <inertial>
        </inertial>
    </link>
    <link name="Frame_FHC2_FOV">
        <inertial>
        </inertial>
    </link>
    <link name="Frame_FHC3_FOV">
        <inertial>
        </inertial>
    </link>
    <link name="Frame_FHC4_FOV">
        <inertial>
        </inertial>
    </link>
    <link name="Frame_RHC1">
        <inertial>
        </inertial>
    </link>
    <link name="Frame_RHC2">
        <inertial>
        </inertial>
    </link>
    <link name="Frame_RHC1_FOV">
        <inertial>
        </inertial>
    </link>
    <link name="Frame_RHC2_FOV">
        <inertial>
        </inertial>
    </link>
    <link name="Frame_ATS1">
        <inertial>
        </inertial>
    </link>
    <link name="Frame_ATS2">
        <inertial>
        </inertial>
    </link>
    <link name="Frame_ATS3">
        <inertial>
        </inertial>
    </link>
    <link name="Frame_ATS4">
        <inertial>
        </inertial>
    </link>
    <link name="Frame_ATS5">
        <inertial>
        </inertial>
    </link>
    <link name="Frame_HS">
        <inertial>
        </inertial>
    </link>
    <link name="Frame_ICU">
        <inertial>
        </inertial>
    </link>
    <link name="Frame_RDS">
        <inertial>
        </inertial>
    </link>
    <link name="Frame_TIRS">
        <inertial>
        </inertial>
    </link>
    <link name="Frame_WS1">
        <inertial>
        </inertial>
    </link>
    <link name="Frame_WS2">
        <inertial>
        </inertial>
    </link>
    <link name="Frame_MOXIE">
        <inertial>
        </inertial>
    </link>
    <link name="Frame_MI">
        <inertial>
        </inertial>
    </link>
    <link name="Frame_MAZ">
        <inertial>
        </inertial>
    </link>
    <link name="Frame_MEL">
        <inertial>
        </inertial>
    </link>
    <link name="Frame_SCI">
        <inertial>
        </inertial>
    </link>
    <link name="Frame_SCRMI">
        <inertial>
        </inertial>
    </link>
    <link name="Frame_SCLIBS">
        <inertial>
        </inertial>
    </link>
    <link name="Frame_SCIR">
        <inertial>
        </inertial>
    </link>
    <link name="Frame_MCL">
        <inertial>
        </inertial>
    </link>
    <link name="Frame_MCR">
        <inertial>
        </inertial>
    </link>
    <link name="Frame_NCL">
        <inertial>
        </inertial>
    </link>
    <link name="Frame_NCR">
        <inertial>
        </inertial>
    </link>
    <link name="Frame_NCL_FOV">
        <inertial>
        </inertial>
    </link>
    <link name="Frame_NCR_FOV">
        <inertial>
        </inertial>
    </link>
    <link name="Frame_ROCKER_L">
        <inertial>
        </inertial>
    </link>
    <link name="Frame_ROCKER_R">
        <inertial>
        </inertial>
    </link>
    <link name="Frame_BOGIE_L">
        <inertial>
        </inertial>
    </link>
    <link name="Frame_BOGIE_R">
        <inertial>
        </inertial>
    </link>
    <link name="Frame_DIFF">
        <inertial>
        </inertial>
    </link>
    <link name="Frame_STEER_LF">
        <inertial>
        </inertial>
    </link>
    <link name="Frame_STEER_LR">
        <inertial>
        </inertial>
    </link>
    <link name="Frame_STEER_RF">
        <inertial>
        </inertial>
    </link>
    <link name="Frame_STEER_RR">
        <inertial>
        </inertial>
    </link>
    <link name="Frame_WHEEL_LF">
        <inertial>
        </inertial>
    </link>
    <link name="Frame_WHEEL_LM">
        <inertial>
        </inertial>
    </link>
    <link name="Frame_WHEEL_LR">
        <inertial>
        </inertial>
    </link>
    <link name="Frame_WHEEL_RF">
        <inertial>
        </inertial>
    </link>
    <link name="Frame_WHEEL_RM">
        <inertial>
        </inertial>
    </link>
    <link name="Frame_WHEEL_RR">
        <inertial>
        </inertial>
    </link>
    <link name="Frame_RIMUA">
        <inertial>
        </inertial>
    </link>
    <link name="Frame_RIMUB">
        <inertial>
        </inertial>
    </link>
    <link name="Frame_RIMFAX">
        <inertial>
        </inertial>
    </link>
    <link name="Frame_HGAS">
        <inertial>
        </inertial>
    </link>
    <link name="Frame_HGAG">
        <inertial>
        </inertial>
    </link>
    <link name="Frame_ANT">
        <inertial>
        </inertial>
    </link>
    <link name="Frame_RA_BASE">
        <inertial>
        </inertial>
    </link>
    <link name="Frame_RA1">
        <inertial>
        </inertial>
    </link>
    <link name="Frame_RA2">
        <inertial>
        </inertial>
    </link>
    <link name="Frame_RA3">
        <inertial>
        </inertial>
    </link>
    <link name="Frame_RA4">
        <inertial>
        </inertial>
    </link>
    <link name="Frame_RA5">
        <inertial>
        </inertial>
    </link>
    <link name="Frame_RA6">
        <inertial>
        </inertial>
    </link>
    <link name="Frame_TURRET">
        <inertial>
        </inertial>
    </link>
    <link name="Frame_DOCKING_POST">
        <inertial>
        </inertial>
    </link>
    <link name="Frame_DRILL">
        <inertial>
        </inertial>
    </link>
    <link name="Frame_FCS">
        <inertial>
        </inertial>
    </link>
    <link name="Frame_GDRT">
        <inertial>
        </inertial>
    </link>
    <link name="Frame_PIXL">
        <inertial>
        </inertial>
    </link>
    <link name="Frame_SHERLOC">
        <inertial>
        </inertial>
    </link>
    <link name="Frame_WATSON">
        <inertial>
        </inertial>
    </link>
    <link name="Frame_CAL_MC1">
        <inertial>
        </inertial>
    </link>
    <link name="Frame_CAL_MC2">
        <inertial>
        </inertial>
    </link>
    <link name="Frame_CAL_SC">
        <inertial>
        </inertial>
    </link>
    <link name="Frame_CAL_PIXL">
        <inertial>
        </inertial>
    </link>
    <link name="Frame_CAL_SHERLOC">
        <inertial>
        </inertial>
    </link>
    <joint name="JointRoot" type="floating">
        <origin xyz="0 0 0" rpy="0 -0 0"/>
        <parent link="ground"/>
        <child link="Body_Chassis"/>
    </joint>
    <joint name="Joint_MHS_DebrisShield" type="floating">
        <origin xyz="0.09002 0 -1.13338" rpy="0 -0 0"/>
        <parent link="Body_Chassis"/>
        <child link="Body_MHS_DebrisShield"/>
    </joint>
    <joint name="CENTER_DIFFERENTIAL" type="revolute">
        <origin xyz="-0.05198 0 -1.13338" rpy="0 -0 0"/>
        <parent link="Body_Chassis"/>
        <child link="Body_Differential"/>
        <axis xyz="0 0 1"/>
        <limit lower="-1.79769e+308" upper="1.79769e+308" effort="1.79769e+308" velocity="1.79769e+308"/>
    </joint>
    <joint name="LEFT_DIFFERENTIAL" type="revolute">
        <origin xyz="0.30402 -0.79959 -0.89288" rpy="0 -0 0"/>
        <parent link="Body_Chassis"/>
        <child link="Body_RockerLeft"/>
        <axis xyz="0 1 0"/>
        <limit lower="-1.79769e+308" upper="1.79769e+308" effort="1.79769e+308" velocity="1.79769e+308"/>
    </joint>
    <joint name="LEFT_BOGIE" type="revolute">
        <origin xyz="-0.754 -0.12 0.23" rpy="0 -0 0"/>
        <parent link="Body_RockerLeft"/>
        <child link="Body_BogieLeft"/>
        <axis xyz="0 1 0"/>
        <limit lower="-1.79769e+308" upper="1.79769e+308" effort="1.79769e+308" velocity="1.79769e+308"/>
    </joint>
    <joint name="LR_STEER" type="revolute">
        <origin xyz="-0.625 -0.14291 0.4" rpy="0 -0 0"/>
        <parent link="Body_BogieLeft"/>
        <child link="Body_SteerLeftRear"/>
        <axis xyz="0 0 1"/>
        <limit lower="-1.79769e+308" upper="1.79769e+308" effort="1.79769e+308" velocity="1.79769e+308"/>
    </joint>
    <joint name="LR_DRIVE" type="revolute">
        <origin xyz="0 0 0" rpy="0 -0 0"/>
        <parent link="Body_SteerLeftRear"/>
        <child link="Body_WheelLeftRear"/>
        <axis xyz="0 -1 0"/>
        <limit lower="-1.79769e+308" upper="1.79769e+308" effort="1.79769e+308" velocity="1.79769e+308"/>
    </joint>
    <joint name="LM_DRIVE" type="revolute">
        <origin xyz="0.44998 -0.26491 0.4" rpy="0 -0 0"/>
        <parent link="Body_BogieLeft"/>
        <child link="Body_WheelLeftMiddle"/>
        <axis xyz="0 -1 0"/>
        <limit lower="-1.79769e+308" upper="1.79769e+308" effort="1.79769e+308" velocity="1.79769e+308"/>
    </joint>
    <joint name="LF_STEER" type="revolute">
        <origin xyz="0.881 -0.26291 0.63" rpy="0 -0 0"/>
        <parent link="Body_RockerLeft"/>
        <child link="Body_SteerLeftFront"/>
        <axis xyz="0 0 1"/>
        <limit lower="-1.79769e+308" upper="1.79769e+308" effort="1.79769e+308" velocity="1.79769e+308"/>
    </joint>
    <joint name="LF_DRIVE" type="revolute">
        <origin xyz="0 0 0" rpy="0 -0 0"/>
        <parent link="Body_SteerLeftFront"/>
        <child link="Body_WheelLeftFront"/>
        <axis xyz="0 -1 0"/>
        <limit lower="-1.79769e+308" upper="1.79769e+308" effort="1.79769e+308" velocity="1.79769e+308"/>
    </joint>
    <joint name="RIGHT_DIFFERENTIAL" type="revolute">
        <origin xyz="0.30402 0.79959 -0.89288" rpy="0 -0 0"/>
        <parent link="Body_Chassis"/>
        <child link="Body_RockerRight"/>
        <axis xyz="0 1 0"/>
        <limit lower="-1.79769e+308" upper="1.79769e+308" effort="1.79769e+308" velocity="1.79769e+308"/>
    </joint>
    <joint name="RIGHT_BOGIE" type="revolute">
        <origin xyz="-0.754 0.12 0.23" rpy="0 -0 0"/>
        <parent link="Body_RockerRight"/>
        <child link="Body_BogieRight"/>
        <axis xyz="0 1 0"/>
        <limit lower="-1.79769e+308" upper="1.79769e+308" effort="1.79769e+308" velocity="1.79769e+308"/>
    </joint>
    <joint name="RR_STEER" type="revolute">
        <origin xyz="-0.625 0.14291 0.4" rpy="0 -0 0"/>
        <parent link="Body_BogieRight"/>
        <child link="Body_SteerRightRear"/>
        <axis xyz="0 0 1"/>
        <limit lower="-1.79769e+308" upper="1.79769e+308" effort="1.79769e+308" velocity="1.79769e+308"/>
    </joint>
    <joint name="RR_DRIVE" type="revolute">
        <origin xyz="0 0 0" rpy="0 -0 0"/>
        <parent link="Body_SteerRightRear"/>
        <child link="Body_WheelRightRear"/>
        <axis xyz="0 -1 0"/>
        <limit lower="-1.79769e+308" upper="1.79769e+308" effort="1.79769e+308" velocity="1.79769e+308"/>
    </joint>
    <joint name="RM_DRIVE" type="revolute">
        <origin xyz="0.44998 0.26491 0.4" rpy="0 -0 0"/>
        <parent link="Body_BogieRight"/>
        <child link="Body_WheelRightMiddle"/>
        <axis xyz="0 -1 0"/>
        <limit lower="-1.79769e+308" upper="1.79769e+308" effort="1.79769e+308" velocity="1.79769e+308"/>
    </joint>
    <joint name="RF_STEER" type="revolute">
        <origin xyz="0.881 0.26291 0.63" rpy="0 -0 0"/>
        <parent link="Body_RockerRight"/>
        <child link="Body_SteerRightFront"/>
        <axis xyz="0 0 1"/>
        <limit lower="-1.79769e+308" upper="1.79769e+308" effort="1.79769e+308" velocity="1.79769e+308"/>
    </joint>
    <joint name="RF_DRIVE" type="revolute">
        <origin xyz="0 0 0" rpy="0 -0 0"/>
        <parent link="Body_SteerRightFront"/>
        <child link="Body_WheelRightFront"/>
        <axis xyz="0 -1 0"/>
        <limit lower="-1.79769e+308" upper="1.79769e+308" effort="1.79769e+308" velocity="1.79769e+308"/>
    </joint>
    <joint name="RSM_AZ_ENC" type="revolute">
        <origin xyz="0.804037 0.559028 -1.91927" rpy="0 -0 3.12414"/>
        <parent link="Body_Chassis"/>
        <child link="Body_RSM_AZ"/>
        <axis xyz="0 0 1"/>
        <limit lower="0" upper="6.31809" effort="1.79769e+308" velocity="1.79769e+308"/>
    </joint>
    <joint name="RSM_EL_ENC" type="revolute">
        <origin xyz="0 0 0" rpy="3.14159 -1.55334 3.14159"/>
        <parent link="Body_RSM_AZ"/>
        <child link="Body_RSM_EL"/>
        <axis xyz="0 1 0"/>
        <limit lower="0" upper="3.1765" effort="1.79769e+308" velocity="1.79769e+308"/>
    </joint>
    <joint name="HGA_AZ" type="revolute">
        <origin xyz="-0.36998 -0.475 -1.13288" rpy="0 -0 0.436332"/>
        <parent link="Body_Chassis"/>
        <child link="Body_HGA_AZ"/>
        <axis xyz="0 0 1"/>
        <limit lower="-1.79769e+308" upper="1.79769e+308" effort="1.79769e+308" velocity="1.79769e+308"/>
    </joint>
    <joint name="HGA_EL" type="revolute">
        <origin xyz="0 0 -0.248" rpy="0.785398 -0 0"/>
        <parent link="Body_HGA_AZ"/>
        <child link="Body_HGA_EL"/>
        <axis xyz="1 0 0"/>
        <limit lower="-1.79769e+308" upper="1.79769e+308" effort="1.79769e+308" velocity="1.79769e+308"/>
    </joint>
    <joint name="JointRobotArmBase" type="fixed">
        <origin xyz="0.09002 0 -1.13338" rpy="0 -0 0"/>
        <parent link="Body_Chassis"/>
        <child link="Body_RA_Base"/>
    </joint>
    <joint name="JOINT1_ENC" type="revolute">
        <origin xyz="1.1756 -0.4515 0.3116" rpy="0 -0 0"/>
        <parent link="Body_RA_Base"/>
        <child link="Body_RA_Link1"/>
        <axis xyz="0 0 1"/>
        <limit lower="-3.145" upper="1.592" effort="1.79769e+308" velocity="1.79769e+308"/>
    </joint>
    <joint name="JOINT2_ENC" type="revolute">
        <origin xyz="0.166 0 0" rpy="0 -0 0"/>
        <parent link="Body_RA_Link1"/>
        <child link="Body_RA_Link2"/>
        <axis xyz="0 -1 0"/>
        <limit lower="-3.267" upper="0.126" effort="1.79769e+308" velocity="1.79769e+308"/>
    </joint>
    <joint name="JOINT3_ENC" type="revolute">
        <origin xyz="0.8194 0 0" rpy="0 -0 0"/>
        <parent link="Body_RA_Link2"/>
        <child link="Body_RA_Link3"/>
        <axis xyz="0 -1 0"/>
        <limit lower="-2.866" upper="2.866" effort="1.79769e+308" velocity="1.79769e+308"/>
    </joint>
    <joint name="JOINT4_ENC" type="revolute">
        <origin xyz="0.7533 0 0" rpy="0 -0 0"/>
        <parent link="Body_RA_Link3"/>
        <child link="Body_RA_Link4"/>
        <axis xyz="0 -1 0"/>
        <limit lower="-0.178" upper="3.669" effort="1.79769e+308" velocity="1.79769e+308"/>
    </joint>
    <joint name="JOINT5_ENC" type="revolute">
        <origin xyz="-0.1757 0.1791 0" rpy="0 -0 0"/>
        <parent link="Body_RA_Link4"/>
        <child link="Body_RA_Link5"/>
        <axis xyz="0 0 1"/>
        <limit lower="-0.353" upper="6.636" effort="1.79769e+308" velocity="1.79769e+308"/>
    </joint>
    <joint name="JointTurret" type="fixed">
        <origin xyz="-2.7386 0.2724 -0.3116" rpy="0 -0 0"/>
        <parent link="Body_RA_Link5"/>
        <child link="Body_Turret"/>
    </joint>
    <joint name="DRILL_FEED" type="prismatic">
        <origin xyz="2.5301 -0.272349 -0.0168656" rpy="0 -0 0"/>
        <parent link="Body_Turret"/>
        <child link="Body_CorerFeed"/>
        <axis xyz="1 0 0"/>
        <limit lower="-1.79769e+308" upper="1.79769e+308" effort="1.79769e+308" velocity="1.79769e+308"/>
    </joint>
    <joint name="STABILIZER_LOWER" type="prismatic">
        <origin xyz="2.5301 -0.272349 -0.0168656" rpy="0 -0 0"/>
        <parent link="Body_Turret"/>
        <child link="Body_StabilizerFar"/>
        <axis xyz="-1 0 0"/>
        <limit lower="-1.79769e+308" upper="1.79769e+308" effort="1.79769e+308" velocity="1.79769e+308"/>
    </joint>
    <joint name="STABILIZER_UPPER" type="prismatic">
        <origin xyz="2.5301 -0.272349 -0.0168656" rpy="0 -0 0"/>
        <parent link="Body_Turret"/>
        <child link="Body_StabilizerNear"/>
        <axis xyz="-1 0 0"/>
        <limit lower="-1.79769e+308" upper="1.79769e+308" effort="1.79769e+308" velocity="1.79769e+308"/>
    </joint>
    <joint name="WATSON_CAP_ENC" type="revolute">
        <origin xyz="2.6025 -0.581204 -0.0309103" rpy="0 -0 0"/>
        <parent link="Body_Turret"/>
        <child link="Body_WATSON_Cap"/>
        <axis xyz="0 0 -1"/>
        <limit lower="-1.79769e+308" upper="1.79769e+308" effort="1.79769e+308" velocity="1.79769e+308"/>
    </joint>
    <joint name="SHERLOC_CAP_ENC" type="revolute">
        <origin xyz="2.86084 -0.58439 0.0124626" rpy="0 -0 0"/>
        <parent link="Body_Turret"/>
        <child link="Body_SHERLOC_Cap"/>
        <axis xyz="0 0 -1"/>
        <limit lower="-1.79769e+308" upper="1.79769e+308" effort="1.79769e+308" velocity="1.79769e+308"/>
    </joint>
    <joint name="Joint_for_Frame_RNAV" type="fixed">
        <origin xyz="0 0 0" rpy="0 -0 0"/>
        <parent link="Body_Chassis"/>
        <child link="Frame_RNAV"/>
    </joint>
    <joint name="Joint_for_Frame_RMECH" type="fixed">
        <origin xyz="0.09002 0 -1.13338" rpy="0 -0 0"/>
        <parent link="Body_Chassis"/>
        <child link="Frame_RMECH"/>
    </joint>
    <joint name="Joint_for_Frame_FHCB" type="fixed">
        <origin xyz="0.95652 0.074 -0.76858" rpy="0 -0 0"/>
        <parent link="Body_Chassis"/>
        <child link="Frame_FHCB"/>
    </joint>
    <joint name="Joint_for_Frame_FHC1" type="fixed">
        <origin xyz="1.03958 0.226094 -0.760608" rpy="-0.174841 1.117 -0.000247676"/>
        <parent link="Body_Chassis"/>
        <child link="Frame_FHC1"/>
    </joint>
    <joint name="Joint_for_Frame_FHC2" type="fixed">
        <origin xyz="1.05159 -0.002264 -0.754746" rpy="0.174841 1.117 0.000247676"/>
        <parent link="Body_Chassis"/>
        <child link="Frame_FHC2"/>
    </joint>
    <joint name="Joint_for_Frame_FHC3" type="fixed">
        <origin xyz="1.05159 0.150264 -0.754746" rpy="-0.174841 1.117 -0.000247676"/>
        <parent link="Body_Chassis"/>
        <child link="Frame_FHC3"/>
    </joint>
    <joint name="Joint_for_Frame_FHC4" type="fixed">
        <origin xyz="1.03958 -0.078094 -0.760608" rpy="0.174841 1.117 0.000247676"/>
        <parent link="Body_Chassis"/>
        <child link="Frame_FHC4"/>
    </joint>
    <joint name="Joint_for_Frame_FHC1_FOV" type="fixed">
        <origin xyz="1.09534 0.237039 -0.733411" rpy="-0.174841 1.117 -0.000247676"/>
        <parent link="Body_Chassis"/>
        <child link="Frame_FHC1_FOV"/>
    </joint>
    <joint name="Joint_for_Frame_FHC2_FOV" type="fixed">
        <origin xyz="1.10736 -0.0132091 -0.727549" rpy="0.174841 1.117 0.000247676"/>
        <parent link="Body_Chassis"/>
        <child link="Frame_FHC2_FOV"/>
    </joint>
    <joint name="Joint_for_Frame_FHC3_FOV" type="fixed">
        <origin xyz="1.10736 0.161209 -0.727549" rpy="-0.174841 1.117 -0.000247676"/>
        <parent link="Body_Chassis"/>
        <child link="Frame_FHC3_FOV"/>
    </joint>
    <joint name="Joint_for_Frame_FHC4_FOV" type="fixed">
        <origin xyz="1.09534 -0.0890391 -0.733411" rpy="0.174841 1.117 0.000247676"/>
        <parent link="Body_Chassis"/>
        <child link="Frame_FHC4_FOV"/>
    </joint>
    <joint name="Joint_for_Frame_RHC1" type="fixed">
        <origin xyz="-1.00766 -0.467 -0.77468" rpy="-2.99453e-22 0.785336 3.14159"/>
        <parent link="Body_Chassis"/>
        <child link="Frame_RHC1"/>
    </joint>
    <joint name="Joint_for_Frame_RHC2" type="fixed">
        <origin xyz="-1.00766 0.467 -0.77468" rpy="-2.99453e-22 0.785336 3.14159"/>
        <parent link="Body_Chassis"/>
        <child link="Frame_RHC2"/>
    </joint>
    <joint name="Joint_for_Frame_RHC1_FOV" type="fixed">
        <origin xyz="-1.0522 -0.467 -0.73013" rpy="-2.99453e-22 0.785336 3.14159"/>
        <parent link="Body_Chassis"/>
        <child link="Frame_RHC1_FOV"/>
    </joint>
    <joint name="Joint_for_Frame_RHC2_FOV" type="fixed">
        <origin xyz="-1.0522 0.467 -0.73013" rpy="-2.99453e-22 0.785336 3.14159"/>
        <parent link="Body_Chassis"/>
        <child link="Frame_RHC2_FOV"/>
    </joint>
    <joint name="Joint_for_Frame_ATS1" type="fixed">
        <origin xyz="0.846027 0.597543 -1.44188" rpy="1.5708 -0 2.44323"/>
        <parent link="Body_Chassis"/>
        <child link="Frame_ATS1"/>
    </joint>
    <joint name="Joint_for_Frame_ATS2" type="fixed">
        <origin xyz="0.749647 0.576177 -1.49028" rpy="-1.5708 -0 1.13391"/>
        <parent link="Body_Chassis"/>
        <child link="Frame_ATS2"/>
    </joint>
    <joint name="Joint_for_Frame_ATS3" type="fixed">
        <origin xyz="0.816326 0.50341 -1.44188" rpy="1.5708 -0 0.348992"/>
        <parent link="Body_Chassis"/>
        <child link="Frame_ATS3"/>
    </joint>
    <joint name="Joint_for_Frame_ATS4" type="fixed">
        <origin xyz="0.896872 -0.63405 -0.879074" rpy="-1.5708 -0 -1.5708"/>
        <parent link="Body_Chassis"/>
        <child link="Frame_ATS4"/>
    </joint>
    <joint name="Joint_for_Frame_ATS5" type="fixed">
        <origin xyz="0.896872 0.63405 -0.830674" rpy="1.5708 -0 1.5708"/>
        <parent link="Body_Chassis"/>
        <child link="Frame_ATS5"/>
    </joint>
    <joint name="Joint_for_Frame_HS" type="fixed">
        <origin xyz="0.743443 0.576337 -1.50598" rpy="-0.463643 1.57079 0.463643"/>
        <parent link="Body_Chassis"/>
        <child link="Frame_HS"/>
    </joint>
    <joint name="Joint_for_Frame_ICU" type="fixed">
        <origin xyz="0.179008 -0.209 -1.04738" rpy="3.14159 -0 0"/>
        <parent link="Body_Chassis"/>
        <child link="Frame_ICU"/>
    </joint>
    <joint name="Joint_for_Frame_RDS" type="fixed">
        <origin xyz="0.138992 -0.298597 -1.17948" rpy="3.14159 -2.64698e-23 -0.157044"/>
        <parent link="Body_Chassis"/>
        <child link="Frame_RDS"/>
    </joint>
    <joint name="Joint_for_Frame_TIRS" type="fixed">
        <origin xyz="0.802591 0.616374 -1.55388" rpy="0 -0 -1.53621"/>
        <parent link="Body_Chassis"/>
        <child link="Frame_TIRS"/>
    </joint>
    <joint name="Joint_for_Frame_WS1" type="fixed">
        <origin xyz="0.854257 0.597514 -1.59588" rpy="0 -0 0.104166"/>
        <parent link="Body_Chassis"/>
        <child link="Frame_WS1"/>
    </joint>
    <joint name="Joint_for_Frame_WS2" type="fixed">
        <origin xyz="0.801386 0.623898 -1.62438" rpy="0 -0 2.19924"/>
        <parent link="Body_Chassis"/>
        <child link="Frame_WS2"/>
    </joint>
    <joint name="Joint_for_Frame_MOXIE" type="fixed">
        <origin xyz="-0.193552 -0.508 -1.04738" rpy="0 -0 0"/>
        <parent link="Body_Chassis"/>
        <child link="Frame_MOXIE"/>
    </joint>
    <joint name="Joint_for_Frame_MI" type="fixed">
        <origin xyz="0.804037 0.559028 -1.13288" rpy="0 -0 0"/>
        <parent link="Body_Chassis"/>
        <child link="Frame_MI"/>
    </joint>
    <joint name="Joint_for_Frame_MAZ" type="fixed">
        <origin xyz="0 0 0" rpy="0 -0 0"/>
        <parent link="Body_RSM_AZ"/>
        <child link="Frame_MAZ"/>
    </joint>
    <joint name="Joint_for_Frame_MEL" type="fixed">
        <origin xyz="0 0 0" rpy="-1.5708 -0 0"/>
        <parent link="Body_RSM_EL"/>
        <child link="Frame_MEL"/>
    </joint>
    <joint name="Joint_for_Frame_SCI" type="fixed">
        <origin xyz="-0.071379 -0.112 -0.114609" rpy="3.14159 -0 0"/>
        <parent link="Body_RSM_EL"/>
        <child link="Frame_SCI"/>
    </joint>
    <joint name="Joint_for_Frame_SCRMI" type="fixed">
        <origin xyz="-0.062479 -0.112 -0.213609" rpy="3.14159 -0 0"/>
        <parent link="Body_RSM_EL"/>
        <child link="Frame_SCRMI"/>
    </joint>
    <joint name="Joint_for_Frame_SCLIBS" type="fixed">
        <origin xyz="-0.062479 -0.112 -0.213609" rpy="3.14159 -0 0"/>
        <parent link="Body_RSM_EL"/>
        <child link="Frame_SCLIBS"/>
    </joint>
    <joint name="Joint_for_Frame_SCIR" type="fixed">
        <origin xyz="-0.062479 -0.112 -0.213609" rpy="3.14159 -0 0"/>
        <parent link="Body_RSM_EL"/>
        <child link="Frame_SCIR"/>
    </joint>
    <joint name="Joint_for_Frame_MCL" type="fixed">
        <origin xyz="-0.085135 -0.126634 -0.065127" rpy="0 -0 0.0219954"/>
        <parent link="Body_RSM_EL"/>
        <child link="Frame_MCL"/>
    </joint>
    <joint name="Joint_for_Frame_MCR" type="fixed">
        <origin xyz="-0.085134 0.121506 -0.065128" rpy="0 -0 -0.0220028"/>
        <parent link="Body_RSM_EL"/>
        <child link="Frame_MCR"/>
    </joint>
    <joint name="Joint_for_Frame_NCL" type="fixed">
        <origin xyz="0.080595 -0.214392 -0.057109" rpy="1.57079 1.57079 1.57079"/>
        <parent link="Body_RSM_EL"/>
        <child link="Frame_NCL"/>
    </joint>
    <joint name="Joint_for_Frame_NCR" type="fixed">
        <origin xyz="0.080595 0.209607 -0.057111" rpy="1.57079 1.57079 1.57079"/>
        <parent link="Body_RSM_EL"/>
        <child link="Frame_NCR"/>
    </joint>
    <joint name="Joint_for_Frame_NCL_FOV" type="fixed">
        <origin xyz="0.143595 -0.214392 -0.057109" rpy="1.57079 1.57079 1.57079"/>
        <parent link="Body_RSM_EL"/>
        <child link="Frame_NCL_FOV"/>
    </joint>
    <joint name="Joint_for_Frame_NCR_FOV" type="fixed">
        <origin xyz="0.143595 0.209607 -0.057111" rpy="1.57079 1.57079 1.57079"/>
        <parent link="Body_RSM_EL"/>
        <child link="Frame_NCR_FOV"/>
    </joint>
    <joint name="Joint_for_Frame_ROCKER_L" type="fixed">
        <origin xyz="0 0 0" rpy="-1.5708 -0 0"/>
        <parent link="Body_RockerLeft"/>
        <child link="Frame_ROCKER_L"/>
    </joint>
    <joint name="Joint_for_Frame_ROCKER_R" type="fixed">
        <origin xyz="0 0 0" rpy="-1.5708 -0 0"/>
        <parent link="Body_RockerRight"/>
        <child link="Frame_ROCKER_R"/>
    </joint>
    <joint name="Joint_for_Frame_BOGIE_L" type="fixed">
        <origin xyz="0 0 0" rpy="-1.5708 -0 0"/>
        <parent link="Body_BogieLeft"/>
        <child link="Frame_BOGIE_L"/>
    </joint>
    <joint name="Joint_for_Frame_BOGIE_R" type="fixed">
        <origin xyz="0 0 0" rpy="-1.5708 -0 0"/>
        <parent link="Body_BogieRight"/>
        <child link="Frame_BOGIE_R"/>
    </joint>
    <joint name="Joint_for_Frame_DIFF" type="fixed">
        <origin xyz="0 0 0" rpy="0 -0 0"/>
        <parent link="Body_Differential"/>
        <child link="Frame_DIFF"/>
    </joint>
    <joint name="Joint_for_Frame_STEER_LF" type="fixed">
        <origin xyz="0 0 0" rpy="0 -0 0"/>
        <parent link="Body_SteerLeftFront"/>
        <child link="Frame_STEER_LF"/>
    </joint>
    <joint name="Joint_for_Frame_STEER_LR" type="fixed">
        <origin xyz="0 0 0" rpy="0 -0 0"/>
        <parent link="Body_SteerLeftRear"/>
        <child link="Frame_STEER_LR"/>
    </joint>
    <joint name="Joint_for_Frame_STEER_RF" type="fixed">
        <origin xyz="0 0 0" rpy="0 -0 0"/>
        <parent link="Body_SteerRightFront"/>
        <child link="Frame_STEER_RF"/>
    </joint>
    <joint name="Joint_for_Frame_STEER_RR" type="fixed">
        <origin xyz="0 0 0" rpy="0 -0 0"/>
        <parent link="Body_SteerRightRear"/>
        <child link="Frame_STEER_RR"/>
    </joint>
    <joint name="Joint_for_Frame_WHEEL_LF" type="fixed">
        <origin xyz="0 0 0" rpy="0 -0 0"/>
        <parent link="Body_WheelLeftFront"/>
        <child link="Frame_WHEEL_LF"/>
    </joint>
    <joint name="Joint_for_Frame_WHEEL_LM" type="fixed">
        <origin xyz="0 0 0" rpy="0 -0 0"/>
        <parent link="Body_WheelLeftMiddle"/>
        <child link="Frame_WHEEL_LM"/>
    </joint>
    <joint name="Joint_for_Frame_WHEEL_LR" type="fixed">
        <origin xyz="0 0 0" rpy="0 -0 0"/>
        <parent link="Body_WheelLeftRear"/>
        <child link="Frame_WHEEL_LR"/>
    </joint>
    <joint name="Joint_for_Frame_WHEEL_RF" type="fixed">
        <origin xyz="0 0 0" rpy="0 -0 0"/>
        <parent link="Body_WheelRightFront"/>
        <child link="Frame_WHEEL_RF"/>
    </joint>
    <joint name="Joint_for_Frame_WHEEL_RM" type="fixed">
        <origin xyz="0 0 0" rpy="0 -0 0"/>
        <parent link="Body_WheelRightMiddle"/>
        <child link="Frame_WHEEL_RM"/>
    </joint>
    <joint name="Joint_for_Frame_WHEEL_RR" type="fixed">
        <origin xyz="0 0 0" rpy="0 -0 0"/>
        <parent link="Body_WheelRightRear"/>
        <child link="Frame_WHEEL_RR"/>
    </joint>
    <joint name="Joint_for_Frame_RIMUA" type="fixed">
        <origin xyz="0.310906 -0.441586 -1.04738" rpy="0 0 -1.5708"/>
        <parent link="Body_Chassis"/>
        <child link="Frame_RIMUA"/>
    </joint>
    <joint name="Joint_for_Frame_RIMUB" type="fixed">
        <origin xyz="0.403906 -0.441586 -1.04738" rpy="0 0 -1.5708"/>
        <parent link="Body_Chassis"/>
        <child link="Frame_RIMUB"/>
    </joint>
    <joint name="Joint_for_Frame_RIMFAX" type="fixed">
        <origin xyz="-0.79478 0 -0.71724" rpy="-0.686834 -5.55112e-17 1.5708"/>
        <parent link="Body_Chassis"/>
        <child link="Frame_RIMFAX"/>
    </joint>
    <joint name="Joint_for_Frame_HGAS" type="fixed">
        <origin xyz="-0.36998 -0.475 -1.13288" rpy="0 -0 0.436316"/>
        <parent link="Body_Chassis"/>
        <child link="Frame_HGAS"/>
    </joint>
    <joint name="Joint_for_Frame_HGAG" type="fixed">
        <origin xyz="0 0 0" rpy="3.14159 -0 0"/>
        <parent link="Body_HGA_AZ"/>
        <child link="Frame_HGAG"/>
    </joint>
    <joint name="Joint_for_Frame_ANT" type="fixed">
        <origin xyz="0.2084 0 0" rpy="2.35619 -0 0"/>
        <parent link="Body_HGA_EL"/>
        <child link="Frame_ANT"/>
    </joint>
    <joint name="Joint_for_Frame_RA_BASE" type="fixed">
        <origin xyz="0.967871 -0.561 -0.90838" rpy="0 -0 0"/>
        <parent link="Body_Chassis"/>
        <child link="Frame_RA_BASE"/>
    </joint>
    <joint name="Joint_for_Frame_RA1" type="fixed">
        <origin xyz="0 0 0" rpy="0 -0 0"/>
        <parent link="Body_RA_Link1"/>
        <child link="Frame_RA1"/>
    </joint>
    <joint name="Joint_for_Frame_RA2" type="fixed">
        <origin xyz="0 0 0" rpy="1.5708 -0 0"/>
        <parent link="Body_RA_Link2"/>
        <child link="Frame_RA2"/>
    </joint>
    <joint name="Joint_for_Frame_RA3" type="fixed">
        <origin xyz="0 0 0" rpy="1.5708 -0 0"/>
        <parent link="Body_RA_Link3"/>
        <child link="Frame_RA3"/>
    </joint>
    <joint name="Joint_for_Frame_RA4" type="fixed">
        <origin xyz="0 0 0" rpy="1.5708 -0 0"/>
        <parent link="Body_RA_Link4"/>
        <child link="Frame_RA4"/>
    </joint>
    <joint name="Joint_for_Frame_RA5" type="fixed">
        <origin xyz="0 0 0" rpy="0 -0 0"/>
        <parent link="Body_RA_Link5"/>
        <child link="Frame_RA5"/>
    </joint>
    <joint name="Joint_for_Frame_RA6" type="fixed">
        <origin xyz="0 0 -0.208" rpy="0 -0 0"/>
        <parent link="Body_RA_Link5"/>
        <child link="Frame_RA6"/>
    </joint>
    <joint name="Joint_for_Frame_TURRET" type="fixed">
        <origin xyz="0 0 -0.3285" rpy="0 -0 0"/>
        <parent link="Body_RA_Link5"/>
        <child link="Frame_TURRET"/>
    </joint>
    <joint name="Joint_for_Frame_DOCKING_POST" type="fixed">
        <origin xyz="0.29715 0 -0.3285" rpy="0 -0 0"/>
        <parent link="Body_RA_Link5"/>
        <child link="Frame_DOCKING_POST"/>
    </joint>
    <joint name="Joint_for_Frame_DRILL" type="fixed">
        <origin xyz="0.373 0 -0.3285" rpy="0 -0 0"/>
        <parent link="Body_RA_Link5"/>
        <child link="Frame_DRILL"/>
    </joint>
    <joint name="Joint_for_Frame_FCS" type="fixed">
        <origin xyz="-0.37138 0 -0.2704" rpy="0 -0 3.14159"/>
        <parent link="Body_RA_Link5"/>
        <child link="Frame_FCS"/>
    </joint>
    <joint name="Joint_for_Frame_GDRT" type="fixed">
        <origin xyz="-0.283436 0.237831 -0.2625" rpy="0 -0 2.44346"/>
        <parent link="Body_RA_Link5"/>
        <child link="Frame_GDRT"/>
    </joint>
    <joint name="Joint_for_Frame_PIXL" type="fixed">
        <origin xyz="0 0.3577 -0.3385" rpy="0 -0 1.5708"/>
        <parent link="Body_RA_Link5"/>
        <child link="Frame_PIXL"/>
    </joint>
    <joint name="Joint_for_Frame_SHERLOC" type="fixed">
        <origin xyz="0.143585 -0.305411 -0.292126" rpy="0 -0 -1.22173"/>
    </joint>
    <joint name="Joint_for_Frame_WATSON" type="fixed">
    </joint>
    <joint name="Joint_for_Frame_CAL_MC1" type="fixed">
    </joint>
    <joint name="Joint_for_Frame_CAL_MC2" type="fixed">
    </joint>
    <joint name="Joint_for_Frame_CAL_SC" type="fixed">
    </joint>
    <joint name="Joint_for_Frame_CAL_PIXL" type="fixed">
    </joint>
    <joint name="Joint_for_Frame_CAL_SHERLOC" type="fixed">
    </joint>
</robot>
```// filepath: /home/saumya/outdoor_rover_ws/src/m2020_nav_description/urdf/m2020_nav.urdf
<?xml version="1.0" ?>
<!-- This file was generated automatically. [2021_08_18_14_10_08] -->
<!-- [Tool url: git@github.jpl.nasa.gov:CR/rst.git, branch: dev/working, commit_hash: 47e8686b, commit_time: 2021-08-16 19:00:50 -0700] -->

<robot name="Perseverance">
    <link name="ground">
        <inertial>
        </inertial>
    </link>
    <link name="Body_Chassis">
        <inertial>
        </inertial>
        <visual name="VisGeom_CHASSIS">
        </visual>
    </link>
    <link name="Body_MHS_DebrisShield">
        <inertial>
        </inertial>
        <!-- hidden visual element
        <visual name="VisGeom_MHS_DebrisShield">
        </visual>
        -->
    </link>
    <link name="Body_Differential">
        <inertial>
        </inertial>
        <visual name="VisGeom_CenterDifferential">
        </visual>
    </link>
    <link name="Body_RockerLeft">
        <inertial>
        </inertial>
        <visual name="VisGeom_Left_Rocker">
        </visual>
    </link>
    <link name="Body_BogieLeft">
        <inertial>
        </inertial>
        <visual name="VisGeom_Left_Bogie">
        </visual>
    </link>
    <link name="Body_SteerLeftRear">
        <inertial>
        </inertial>
        <visual name="VisGeom_Steer_LeftRear">
        </visual>
    </link>
    <link name="Body_WheelLeftRear">
        <inertial>
        </inertial>
        <visual name="VisGeom_Wheel_LeftRear">
        </visual>
    </link>
    <link name="Body_WheelLeftMiddle">
        <inertial>
        </inertial>
        <visual name="VisGeom_Wheel_LeftMiddle">
        </visual>
    </link>
    <link name="Body_SteerLeftFront">
        <inertial>
        </inertial>
        <visual name="VisGeom_Steer_LeftFront">
        </visual>
    </link>
    <link name="Body_WheelLeftFront">
        <inertial>
        </inertial>
        <visual name="VisGeom_Wheel_LeftFront">
        </visual>
    </link>
    <link name="Body_RockerRight">
        <inertial>
        </inertial>
        <visual name="VisGeom_Right_Rocker">
        </visual>
    </link>
    <link name="Body_BogieRight">
        <inertial>
        </inertial>
        <visual name="VisGeom_Right_Bogie">
        </visual>
    </link>
    <link name="Body_SteerRightRear">
        <inertial>
        </inertial>
        <visual name="VisGeom_Steer_RightRear">
        </visual>
    </link>
    <link name="Body_WheelRightRear">
        <inertial>
        </inertial>
        <visual name="VisGeom_Wheel_RightRear">
        </visual>
    </link>
    <link name="Body_WheelRightMiddle">
        <inertial>
        </inertial>
        <visual name="VisGeom_Wheel_RightMiddle">
        </visual>
    </link>
    <link name="Body_SteerRightFront">
        <inertial>
        </inertial>
        <visual name="VisGeom_Steer_RightFront">
        </visual>
    </link>
    <link name="Body_WheelRightFront">
        <inertial>
        </inertial>
        <visual name="VisGeom_Wheel_RightFront">
        </visual>
    </link>
    <link name="Body_RSM_AZ">
        <inertial>
        </inertial>
        <visual name="VisGeom_RSM">
        </visual>
    </link>
    <link name="Body_RSM_EL">
        <inertial>
        </inertial>
        <visual name="VisGeom_RSM_HEAD">
        </visual>
    </link>
    <link name="Body_HGA_AZ">
        <inertial>
        </inertial>
        <visual name="VisGeom_HGA_AZ">
        </visual>
    </link>
    <link name="Body_HGA_EL">
        <inertial>
        </inertial>
        <visual name="VisGeom_HGA_EL">
        </visual>
    </link>
    <link name="Body_RA_Base">
        <inertial>
        </inertial>
    </link>
    <link name="Body_RA_Link1">
        <inertial>
        </inertial>
        <visual name="VisGeom_Arm_LINK_1">
        </visual>
    </link>
    <link name="Body_RA_Link2">
        <inertial>
        </inertial>
        <visual name="VisGeom_Arm_LINK_2">
        </visual>
    </link>
    <link name="Body_RA_Link3">
        <inertial>
        </inertial>
        <visual name="VisGeom_Arm_LINK_3">
        </visual>
    </link>
    <link name="Body_RA_Link4">
        <inertial>
        </inertial>
        <visual name="VisGeom_Arm_LINK_4">
        </visual>
    </link>
    <link name="Body_RA_Link5">
        <inertial>
        </inertial>
        <visual name="VisGeom_Arm_LINK_5">
        </visual>
    </link>
    <link name="Body_Turret">
        <inertial>
        </inertial>
        <visual name="VisGeom_Turret">
        </visual>
    </link>
    <link name="Body_CorerFeed">
        <inertial>
        </inertial>
        <!-- hidden visual element
        <visual name="VisGeom_LaunchBit">
        </visual>
        -->
        <visual name="VisGeom_AbradingBit">
        </visual>
        <!-- hidden visual element
        <visual name="VisGeom_CoringBit">
        </visual>
        -->
        <!-- hidden visual element
        <visual name="VisGeom_RegolithBit">
        </visual>
        -->
    </link>
    <link name="Body_StabilizerFar">
        <inertial>
        </inertial>
        <visual name="VisGeom_StabilizerFar">
        </visual>
    </link>
    <link name="Body_StabilizerNear">
        <inertial>
        </inertial>
        <visual name="VisGeom_StabilizerNear">
        </visual>
    </link>
    <link name="Body_WATSON_Cap">
        <inertial>
        </inertial>
        <visual name="VisGeom_WATSON_Cap">
        </visual>
    </link>
    <link name="Body_SHERLOC_Cap">
        <inertial>
        </inertial>
        <visual name="VisGeom_SHERLOC_Cap">
        </visual>
    </link>
    <link name="Frame_RNAV">
        <inertial>
        </inertial>
    </link>
    <link name="Frame_RMECH">
        <inertial>
        </inertial>
    </link>
    <link name="Frame_FHCB">
        <inertial>
        </inertial>
    </link>
    <link name="Frame_FHC1">
        <inertial>
        </inertial>
    </link>
    <link name="Frame_FHC2">
        <inertial>
        </inertial>
    </link>
    <link name="Frame_FHC3">
        <inertial>
        </inertial>
    </link>
    <link name="Frame_FHC4">
        <inertial>
        </inertial>
    </link>
    <link name="Frame_FHC1_FOV">
        <inertial>
        </inertial>
    </link>
    <link name="Frame_FHC2_FOV">
        <inertial>
        </inertial>
    </link>
    <link name="Frame_FHC3_FOV">
        <inertial>
        </inertial>
    </link>
    <link name="Frame_FHC4_FOV">
        <inertial>
        </inertial>
    </link>
    <link name="Frame_RHC1">
        <inertial>
        </inertial>
    </link>
    <link name="Frame_RHC2">
        <inertial>
        </inertial>
    </link>
    <link name="Frame_RHC1_FOV">
        <inertial>
        </inertial>
    </link>
    <link name="Frame_RHC2_FOV">
        <inertial>
        </inertial>
    </link>
    <link name="Frame_ATS1">
        <inertial>
        </inertial>
    </link>
    <link name="Frame_ATS2">
        <inertial>
        </inertial>
    </link>
    <link name="Frame_ATS3">
        <inertial>
        </inertial>
    </link>
    <link name="Frame_ATS4">
        <inertial>
        </inertial>
    </link>
    <link name="Frame_ATS5">
        <inertial>
        </inertial>
    </link>
    <link name="Frame_HS">
        <inertial>
        </inertial>
    </link>
    <link name="Frame_ICU">
        <inertial>
        </inertial>
    </link>
    <link name="Frame_RDS">
        <inertial>
        </inertial>
    </link>
    <link name="Frame_TIRS">
        <inertial>
        </inertial>
    </link>
    <link name="Frame_WS1">
        <inertial>
        </inertial>
    </link>
    <link name="Frame_WS2">
        <inertial>
        </inertial>
    </link>
    <link name="Frame_MOXIE">
        <inertial>
        </inertial>
    </link>
    <link name="Frame_MI">
        <inertial>
        </inertial>
    </link>
    <link name="Frame_MAZ">
        <inertial>
        </inertial>
    </link>
    <link name="Frame_MEL">
        <inertial>
        </inertial>
    </link>
    <link name="Frame_SCI">
        <inertial>
        </inertial>
    </link>
    <link name="Frame_SCRMI">
        <inertial>
        </inertial>
    </link>
    <link name="Frame_SCLIBS">
        <inertial>
        </inertial>
    </link>
    <link name="Frame_SCIR">
        <inertial>
        </inertial>
    </link>
    <link name="Frame_MCL">
        <inertial>
        </inertial>
    </link>
    <link name="Frame_MCR">
        <inertial>
        </inertial>
    </link>
    <link name="Frame_NCL">
        <inertial>
        </inertial>
    </link>
    <link name="Frame_NCR">
        <inertial>
        </inertial>
    </link>
    <link name="Frame_NCL_FOV">
        <inertial>
        </inertial>
    </link>
    <link name="Frame_NCR_FOV">
        <inertial>
        </inertial>
    </link>
    <link name="Frame_ROCKER_L">
        <inertial>
        </inertial>
    </link>
    <link name="Frame_ROCKER_R">
        <inertial>
        </inertial>
    </link>
    <link name="Frame_BOGIE_L">
        <inertial>
        </inertial>
    </link>
    <link name="Frame_BOGIE_R">
        <inertial>
        </inertial>
    </link>
    <link name="Frame_DIFF">
        <inertial>
        </inertial>
    </link>
    <link name="Frame_STEER_LF">
        <inertial>
        </inertial>
    </link>
    <link name="Frame_STEER_LR">
        <inertial>
        </inertial>
    </link>
    <link name="Frame_STEER_RF">
        <inertial>
        </inertial>
    </link>
    <link name="Frame_STEER_RR">
        <inertial>
        </inertial>
    </link>
    <link name="Frame_WHEEL_LF">
        <inertial>
        </inertial>
    </link>
    <link name="Frame_WHEEL_LM">
        <inertial>
        </inertial>
    </link>
    <link name="Frame_WHEEL_LR">
        <inertial>
        </inertial>
    </link>
    <link name="Frame_WHEEL_RF">
        <inertial>
        </inertial>
    </link>
    <link name="Frame_WHEEL_RM">
        <inertial>
        </inertial>
    </link>
    <link name="Frame_WHEEL_RR">
        <inertial>
        </inertial>
    </link>
    <link name="Frame_RIMUA">
        <inertial>
        </inertial>
    </link>
    <link name="Frame_RIMUB">
        <inertial>
        </inertial>
    </link>
    <link name="Frame_RIMFAX">
        <inertial>
        </inertial>
    </link>
    <link name="Frame_HGAS">
        <inertial>
        </inertial>
    </link>
    <link name="Frame_HGAG">
        <inertial>
        </inertial>
    </link>
    <link name="Frame_ANT">
        <inertial>
        </inertial>
    </link>
    <link name="Frame_RA_BASE">
        <inertial>
        </inertial>
    </link>
    <link name="Frame_RA1">
        <inertial>
        </inertial>
    </link>
    <link name="Frame_RA2">
        <inertial>
        </inertial>
    </link>
    <link name="Frame_RA3">
        <inertial>
        </inertial>
    </link>
    <link name="Frame_RA4">
        <inertial>
        </inertial>
    </link>
    <link name="Frame_RA5">
        <inertial>
        </inertial>
    </link>
    <link name="Frame_RA6">
        <inertial>
        </inertial>
    </link>
    <link name="Frame_TURRET">
        <inertial>
        </inertial>
    </link>
    <link name="Frame_DOCKING_POST">
        <inertial>
        </inertial>
    </link>
    <link name="Frame_DRILL">
        <inertial>
        </inertial>
    </link>
    <link name="Frame_FCS">
        <inertial>
        </inertial>
    </link>
    <link name="Frame_GDRT">
        <inertial>
        </inertial>
    </link>
    <link name="Frame_PIXL">
        <inertial>
        </inertial>
    </link>
    <link name="Frame_SHERLOC">
        <inertial>
        </inertial>
    </link>
    <link name="Frame_WATSON">
        <inertial>
        </inertial>
    </link>
    <link name="Frame_CAL_MC1">
        <inertial>
        </inertial>
    </link>
    <link name="Frame_CAL_MC2">
        <inertial>
        </inertial>
    </link>
    <link name="Frame_CAL_SC">
        <inertial>
        </inertial>
    </link>
    <link name="Frame_CAL_PIXL">
        <inertial>
        </inertial>
    </link>
    <link name="Frame_CAL_SHERLOC">
        <inertial>
        </inertial>
    </link>
    <joint name="JointRoot" type="floating">
        <origin xyz="0 0 0" rpy="0 -0 0"/>
        <parent link="ground"/>
        <child link="Body_Chassis"/>
    </joint>
    <joint name="Joint_MHS_DebrisShield" type="floating">
        <origin xyz="0.09002 0 -1.13338" rpy="0 -0 0"/>
        <parent link="Body_Chassis"/>
        <child link="Body_MHS_DebrisShield"/>
    </joint>
    <joint name="CENTER_DIFFERENTIAL" type="revolute">
        <origin xyz="-0.05198 0 -1.13338" rpy="0 -0 0"/>
        <parent link="Body_Chassis"/>
        <child link="Body_Differential"/>
        <axis xyz="0 0 1"/>
        <limit lower="-1.79769e+308" upper="1.79769e+308" effort="1.79769e+308" velocity="1.79769e+308"/>
    </joint>
    <joint name="LEFT_DIFFERENTIAL" type="revolute">
        <origin xyz="0.30402 -0.79959 -0.89288" rpy="0 -0 0"/>
        <parent link="Body_Chassis"/>
        <child link="Body_RockerLeft"/>
        <axis xyz="0 1 0"/>
        <limit lower="-1.79769e+308" upper="1.79769e+308" effort="1.79769e+308" velocity="1.79769e+308"/>
    </joint>
    <joint name="LEFT_BOGIE" type="revolute">
        <origin xyz="-0.754 -0.12 0.23" rpy="0 -0 0"/>
        <parent link="Body_RockerLeft"/>
        <child link="Body_BogieLeft"/>
        <axis xyz="0 1 0"/>
        <limit lower="-1.79769e+308" upper="1.79769e+308" effort="1.79769e+308" velocity="1.79769e+308"/>
    </joint>
    <joint name="LR_STEER" type="revolute">
        <origin xyz="-0.625 -0.14291 0.4" rpy="0 -0 0"/>
        <parent link="Body_BogieLeft"/>
        <child link="Body_SteerLeftRear"/>
        <axis xyz="0 0 1"/>
        <limit lower="-1.79769e+308" upper="1.79769e+308" effort="1.79769e+308" velocity="1.79769e+308"/>
    </joint>
    <joint name="LR_DRIVE" type="revolute">
        <origin xyz="0 0 0" rpy="0 -0 0"/>
        <parent link="Body_SteerLeftRear"/>
        <child link="Body_WheelLeftRear"/>
        <axis xyz="0 -1 0"/>
        <limit lower="-1.79769e+308" upper="1.79769e+308" effort="1.79769e+308" velocity="1.79769e+308"/>
    </joint>
    <joint name="LM_DRIVE" type="revolute">
        <origin xyz="0.44998 -0.26491 0.4" rpy="0 -0 0"/>
        <parent link="Body_BogieLeft"/>
        <child link="Body_WheelLeftMiddle"/>
        <axis xyz="0 -1 0"/>
        <limit lower="-1.79769e+308" upper="1.79769e+308" effort="1.79769e+308" velocity="1.79769e+308"/>
    </joint>
    <joint name="LF_STEER" type="revolute">
        <origin xyz="0.881 -0.26291 0.63" rpy="0 -0 0"/>
        <parent link="Body_RockerLeft"/>
        <child link="Body_SteerLeftFront"/>
        <axis xyz="0 0 1"/>
        <limit lower="-1.79769e+308" upper="1.79769e+308" effort="1.79769e+308" velocity="1.79769e+308"/>
    </joint>
    <joint name="LF_DRIVE" type="revolute">
        <origin xyz="0 0 0" rpy="0 -0 0"/>
        <parent link="Body_SteerLeftFront"/>
        <child link="Body_WheelLeftFront"/>
        <axis xyz="0 -1 0"/>
        <limit lower="-1.79769e+308" upper="1.79769e+308" effort="1.79769e+308" velocity="1.79769e+308"/>
    </joint>
    <joint name="RIGHT_DIFFERENTIAL" type="revolute">
        <origin xyz="0.30402 0.79959 -0.89288" rpy="0 -0 0"/>
        <parent link="Body_Chassis"/>
        <child link="Body_RockerRight"/>
        <axis xyz="0 1 0"/>
        <limit lower="-1.79769e+308" upper="1.79769e+308" effort="1.79769e+308" velocity="1.79769e+308"/>
    </joint>
    <joint name="RIGHT_BOGIE" type="revolute">
        <origin xyz="-0.754 0.12 0.23" rpy="0 -0 0"/>
        <parent link="Body_RockerRight"/>
        <child link="Body_BogieRight"/>
        <axis xyz="0 1 0"/>
        <limit lower="-1.79769e+308" upper="1.79769e+308" effort="1.79769e+308" velocity="1.79769e+308"/>
    </joint>
    <joint name="RR_STEER" type="revolute">
        <origin xyz="-0.625 0.14291 0.4" rpy="0 -0 0"/>
        <parent link="Body_BogieRight"/>
        <child link="Body_SteerRightRear"/>
        <axis xyz="0 0 1"/>
        <limit lower="-1.79769e+308" upper="1.79769e+308" effort="1.79769e+308" velocity="1.79769e+308"/>
    </joint>
    <joint name="RR_DRIVE" type="revolute">
        <origin xyz="0 0 0" rpy="0 -0 0"/>
        <parent link="Body_SteerRightRear"/>
        <child link="Body_WheelRightRear"/>
        <axis xyz="0 -1 0"/>
        <limit lower="-1.79769e+308" upper="1.79769e+308" effort="1.79769e+308" velocity="1.79769e+308"/>
    </joint>
    <joint name="RM_DRIVE" type="revolute">
        <origin xyz="0.44998 0.26491 0.4" rpy="0 -0 0"/>
        <parent link="Body_BogieRight"/>
        <child link="Body_WheelRightMiddle"/>
        <axis xyz="0 -1 0"/>
        <limit lower="-1.79769e+308" upper="1.79769e+308" effort="1.79769e+308" velocity="1.79769e+308"/>
    </joint>
    <joint name="RF_STEER" type="revolute">
        <origin xyz="0.881 0.26291 0.63" rpy="0 -0 0"/>
        <parent link="Body_RockerRight"/>
        <child link="Body_SteerRightFront"/>
        <axis xyz="0 0 1"/>
        <limit lower="-1.79769e+308" upper="1.79769e+308" effort="1.79769e+308" velocity="1.79769e+308"/>
    </joint>
    <joint name="RF_DRIVE" type="revolute">
        <origin xyz="0 0 0" rpy="0 -0 0"/>
        <parent link="Body_SteerRightFront"/>
        <child link="Body_WheelRightFront"/>
        <axis xyz="0 -1 0"/>
        <limit lower="-1.79769e+308" upper="1.79769e+308" effort="1.79769e+308" velocity="1.79769e+308"/>
    </joint>
    <joint name="RSM_AZ_ENC" type="revolute">
        <origin xyz="0.804037 0.559028 -1.91927" rpy="0 -0 3.12414"/>
        <parent link="Body_Chassis"/>
        <child link="Body_RSM_AZ"/>
        <axis xyz="0 0 1"/>
        <limit lower="0" upper="6.31809" effort="1.79769e+308" velocity="1.79769e+308"/>
    </joint>
    <joint name="RSM_EL_ENC" type="revolute">
        <origin xyz="0 0 0" rpy="3.14159 -1.55334 3.14159"/>
        <parent link="Body_RSM_AZ"/>
        <child link="Body_RSM_EL"/>
        <axis xyz="0 1 0"/>
        <limit lower="0" upper="3.1765" effort="1.79769e+308" velocity="1.79769e+308"/>
    </joint>
    <joint name="HGA_AZ" type="revolute">
        <origin xyz="-0.36998 -0.475 -1.13288" rpy="0 -0 0.436332"/>
        <parent link="Body_Chassis"/>
        <child link="Body_HGA_AZ"/>
        <axis xyz="0 0 1"/>
        <limit lower="-1.79769e+308" upper="1.79769e+308" effort="1.79769e+308" velocity="1.79769e+308"/>
    </joint>
    <joint name="HGA_EL" type="revolute">
        <origin xyz="0 0 -0.248" rpy="0.785398 -0 0"/>
        <parent link="Body_HGA_AZ"/>
        <child link="Body_HGA_EL"/>
        <axis xyz="1 0 0"/>
        <limit lower="-1.79769e+308" upper="1.79769e+308" effort="1.79769e+308" velocity="1.79769e+308"/>
    </joint>
    <joint name="JointRobotArmBase" type="fixed">
        <origin xyz="0.09002 0 -1.13338" rpy="0 -0 0"/>
        <parent link="Body_Chassis"/>
        <child link="Body_RA_Base"/>
    </joint>
    <joint name="JOINT1_ENC" type="revolute">
        <origin xyz="1.1756 -0.4515 0.3116" rpy="0 -0 0"/>
        <parent link="Body_RA_Base"/>
        <child link="Body_RA_Link1"/>
        <axis xyz="0 0 1"/>
        <limit lower="-3.145" upper="1.592" effort="1.79769e+308" velocity="1.79769e+308"/>
    </joint>
    <joint name="JOINT2_ENC" type="revolute">
        <origin xyz="0.166 0 0" rpy="0 -0 0"/>
        <parent link="Body_RA_Link1"/>
        <child link="Body_RA_Link2"/>
        <axis xyz="0 -1 0"/>
        <limit lower="-3.267" upper="0.126" effort="1.79769e+308" velocity="1.79769e+308"/>
    </joint>
    <joint name="JOINT3_ENC" type="revolute">
        <origin xyz="0.8194 0 0" rpy="0 -0 0"/>
        <parent link="Body_RA_Link2"/>
        <child link="Body_RA_Link3"/>
        <axis xyz="0 -1 0"/>
        <limit lower="-2.866" upper="2.866" effort="1.79769e+308" velocity="1.79769e+308"/>
    </joint>
    <joint name="JOINT4_ENC" type="revolute">
        <origin xyz="0.7533 0 0" rpy="0 -0 0"/>
        <parent link="Body_RA_Link3"/>
        <child link="Body_RA_Link4"/>
        <axis xyz="0 -1 0"/>
        <limit lower="-0.178" upper="3.669" effort="1.79769e+308" velocity="1.79769e+308"/>
    </joint>
    <joint name="JOINT5_ENC" type="revolute">
        <origin xyz="-0.1757 0.1791 0" rpy="0 -0 0"/>
        <parent link="Body_RA_Link4"/>
        <child link="Body_RA_Link5"/>
        <axis xyz="0 0 1"/>
        <limit lower="-0.353" upper="6.636" effort="1.79769e+308" velocity="1.79769e+308"/>
    </joint>
    <joint name="JointTurret" type="fixed">
        <origin xyz="-2.7386 0.2724 -0.3116" rpy="0 -0 0"/>
        <parent link="Body_RA_Link5"/>
        <child link="Body_Turret"/>
    </joint>
    <joint name="DRILL_FEED" type="prismatic">
        <origin xyz="2.5301 -0.272349 -0.0168656" rpy="0 -0 0"/>
        <parent link="Body_Turret"/>
        <child link="Body_CorerFeed"/>
        <axis xyz="1 0 0"/>
        <limit lower="-1.79769e+308" upper="1.79769e+308" effort="1.79769e+308" velocity="1.79769e+308"/>
    </joint>
    <joint name="STABILIZER_LOWER" type="prismatic">
        <origin xyz="2.5301 -0.272349 -0.0168656" rpy="0 -0 0"/>
        <parent link="Body_Turret"/>
        <child link="Body_StabilizerFar"/>
        <axis xyz="-1 0 0"/>
        <limit lower="-1.79769e+308" upper="1.79769e+308" effort="1.79769e+308" velocity="1.79769e+308"/>
    </joint>
    <joint name="STABILIZER_UPPER" type="prismatic">
        <origin xyz="2.5301 -0.272349 -0.0168656" rpy="0 -0 0"/>
        <parent link="Body_Turret"/>
        <child link="Body_StabilizerNear"/>
        <axis xyz="-1 0 0"/>
        <limit lower="-1.79769e+308" upper="1.79769e+308" effort="1.79769e+308" velocity="1.79769e+308"/>
    </joint>
    <joint name="WATSON_CAP_ENC" type="revolute">
        <origin xyz="2.6025 -0.581204 -0.0309103" rpy="0 -0 0"/>
        <parent link="Body_Turret"/>
        <child link="Body_WATSON_Cap"/>
        <axis xyz="0 0 -1"/>
        <limit lower="-1.79769e+308" upper="1.79769e+308" effort="1.79769e+308" velocity="1.79769e+308"/>
    </joint>
    <joint name="SHERLOC_CAP_ENC" type="revolute">
        <origin xyz="2.86084 -0.58439 0.0124626" rpy="0 -0 0"/>
        <parent link="Body_Turret"/>
        <child link="Body_SHERLOC_Cap"/>
        <axis xyz="0 0 -1"/>
        <limit lower="-1.79769e+308" upper="1.79769e+308" effort="1.79769e+308" velocity="1.79769e+308"/>
    </joint>
    <joint name="Joint_for_Frame_RNAV" type="fixed">
        <origin xyz="0 0 0" rpy="0 -0 0"/>
        <parent link="Body_Chassis"/>
        <child link="Frame_RNAV"/>
    </joint>
    <joint name="Joint_for_Frame_RMECH" type="fixed">
        <origin xyz="0.09002 0 -1.13338" rpy="0 -0 0"/>
        <parent link="Body_Chassis"/>
        <child link="Frame_RMECH"/>
    </joint>
    <joint name="Joint_for_Frame_FHCB" type="fixed">
        <origin xyz="0.95652 0.074 -0.76858" rpy="0 -0 0"/>
        <parent link="Body_Chassis"/>
        <child link="Frame_FHCB"/>
    </joint>
    <joint name="Joint_for_Frame_FHC1" type="fixed">
        <origin xyz="1.03958 0.226094 -0.760608" rpy="-0.174841 1.117 -0.000247676"/>
        <parent link="Body_Chassis"/>
        <child link="Frame_FHC1"/>
    </joint>
    <joint name="Joint_for_Frame_FHC2" type="fixed">
        <origin xyz="1.05159 -0.002264 -0.754746" rpy="0.174841 1.117 0.000247676"/>
        <parent link="Body_Chassis"/>
        <child link="Frame_FHC2"/>
    </joint>
    <joint name="Joint_for_Frame_FHC3" type="fixed">
        <origin xyz="1.05159 0.150264 -0.754746" rpy="-0.174841 1.117 -0.000247676"/>
        <parent link="Body_Chassis"/>
        <child link="Frame_FHC3"/>
    </joint>
    <joint name="Joint_for_Frame_FHC4" type="fixed">
        <origin xyz="1.03958 -0.078094 -0.760608" rpy="0.174841 1.117 0.000247676"/>
        <parent link="Body_Chassis"/>
        <child link="Frame_FHC4"/>
    </joint>
    <joint name="Joint_for_Frame_FHC1_FOV" type="fixed">
        <origin xyz="1.09534 0.237039 -0.733411" rpy="-0.174841 1.117 -0.000247676"/>
        <parent link="Body_Chassis"/>
        <child link="Frame_FHC1_FOV"/>
    </joint>
    <joint name="Joint_for_Frame_FHC2_FOV" type="fixed">
        <origin xyz="1.10736 -0.0132091 -0.727549" rpy="0.174841 1.117 0.000247676"/>
        <parent link="Body_Chassis"/>
        <child link="Frame_FHC2_FOV"/>
    </joint>
    <joint name="Joint_for_Frame_FHC3_FOV" type="fixed">
        <origin xyz="1.10736 0.161209 -0.727549" rpy="-0.174841 1.117 -0.000247676"/>
        <parent link="Body_Chassis"/>
        <child link="Frame_FHC3_FOV"/>
    </joint>
    <joint name="Joint_for_Frame_FHC4_FOV" type="fixed">
        <origin xyz="1.09534 -0.0890391 -0.733411" rpy="0.174841 1.117 0.000247676"/>
        <parent link="Body_Chassis"/>
        <child link="Frame_FHC4_FOV"/>
    </joint>
    <joint name="Joint_for_Frame_RHC1" type="fixed">
        <origin xyz="-1.00766 -0.467 -0.77468" rpy="-2.99453e-22 0.785336 3.14159"/>
        <parent link="Body_Chassis"/>
        <child link="Frame_RHC1"/>
    </joint>
    <joint name="Joint_for_Frame_RHC2" type="fixed">
        <origin xyz="-1.00766 0.467 -0.77468" rpy="-2.99453e-22 0.785336 3.14159"/>
        <parent link="Body_Chassis"/>
        <child link="Frame_RHC2"/>
    </joint>
    <joint name="Joint_for_Frame_RHC1_FOV" type="fixed">
        <origin xyz="-1.0522 -0.467 -0.73013" rpy="-2.99453e-22 0.785336 3.14159"/>
        <parent link="Body_Chassis"/>
        <child link="Frame_RHC1_FOV"/>
    </joint>
    <joint name="Joint_for_Frame_RHC2_FOV" type="fixed">
        <origin xyz="-1.0522 0.467 -0.73013" rpy="-2.99453e-22 0.785336 3.14159"/>
        <parent link="Body_Chassis"/>
        <child link="Frame_RHC2_FOV"/>
    </joint>
    <joint name="Joint_for_Frame_ATS1" type="fixed">
        <origin xyz="0.846027 0.597543 -1.44188" rpy="1.5708 -0 2.44323"/>
        <parent link="Body_Chassis"/>
        <child link="Frame_ATS1"/>
    </joint>
    <joint name="Joint_for_Frame_ATS2" type="fixed">
        <origin xyz="0.749647 0.576177 -1.49028" rpy="-1.5708 -0 1.13391"/>
        <parent link="Body_Chassis"/>
        <child link="Frame_ATS2"/>
    </joint>
    <joint name="Joint_for_Frame_ATS3" type="fixed">
        <origin xyz="0.816326 0.50341 -1.44188" rpy="1.5708 -0 0.348992"/>
        <parent link="Body_Chassis"/>
        <child link="Frame_ATS3"/>
    </joint>
    <joint name="Joint_for_Frame_ATS4" type="fixed">
        <origin xyz="0.896872 -0.63405 -0.879074" rpy="-1.5708 -0 -1.5708"/>
        <parent link="Body_Chassis"/>
        <child link="Frame_ATS4"/>
    </joint>
    <joint name="Joint_for_Frame_ATS5" type="fixed">
        <origin xyz="0.896872 0.63405 -0.830674" rpy="1.5708 -0 1.5708"/>
        <parent link="Body_Chassis"/>
        <child link="Frame_ATS5"/>
    </joint>
    <joint name="Joint_for_Frame_HS" type="fixed">
        <origin xyz="0.743443 0.576337 -1.50598" rpy="-0.463643 1.57079 0.463643"/>
        <parent link="Body_Chassis"/>
        <child link="Frame_HS"/>
    </joint>
    <joint name="Joint_for_Frame_ICU" type="fixed">
        <origin xyz="0.179008 -0.209 -1.04738" rpy="3.14159 -0 0"/>
        <parent link="Body_Chassis"/>
        <child link="Frame_ICU"/>
    </joint>
    <joint name="Joint_for_Frame_RDS" type="fixed">
        <origin xyz="0.138992 -0.298597 -1.17948" rpy="3.14159 -2.64698e-23 -0.157044"/>
        <parent link="Body_Chassis"/>
        <child link="Frame_RDS"/>
    </joint>
    <joint name="Joint_for_Frame_TIRS" type="fixed">
        <origin xyz="0.802591 0.616374 -1.55388" rpy="0 -0 -1.53621"/>
        <parent link="Body_Chassis"/>
        <child link="Frame_TIRS"/>
    </joint>
    <joint name="Joint_for_Frame_WS1" type="fixed">
        <origin xyz="0.854257 0.597514 -1.59588" rpy="0 -0 0.104166"/>
        <parent link="Body_Chassis"/>
        <child link="Frame_WS1"/>
    </joint>
    <joint name="Joint_for_Frame_WS2" type="fixed">
        <origin xyz="0.801386 0.623898 -1.62438" rpy="0 -0 2.19924"/>
        <parent link="Body_Chassis"/>
        <child link="Frame_WS2"/>
    </joint>
    <joint name="Joint_for_Frame_MOXIE" type="fixed">
        <origin xyz="-0.193552 -0.508 -1.04738" rpy="0 -0 0"/>
        <parent link="Body_Chassis"/>
        <child link="Frame_MOXIE"/>
    </joint>
    <joint name="Joint_for_Frame_MI" type="fixed">
        <origin xyz="0.804037 0.559028 -1.13288" rpy="0 -0 0"/>
        <parent link="Body_Chassis"/>
        <child link="Frame_MI"/>
    </joint>
    <joint name="Joint_for_Frame_MAZ" type="fixed">
        <origin xyz="0 0 0" rpy="0 -0 0"/>
        <parent link="Body_RSM_AZ"/>
        <child link="Frame_MAZ"/>
    </joint>
    <joint name="Joint_for_Frame_MEL" type="fixed">
        <origin xyz="0 0 0" rpy="-1.5708 -0 0"/>
        <parent link="Body_RSM_EL"/>
        <child link="Frame_MEL"/>
    </joint>
    <joint name="Joint_for_Frame_SCI" type="fixed">
        <origin xyz="-0.071379 -0.112 -0.114609" rpy="3.14159 -0 0"/>
        <parent link="Body_RSM_EL"/>
        <child link="Frame_SCI"/>
    </joint>
    <joint name="Joint_for_Frame_SCRMI" type="fixed">
        <origin xyz="-0.062479 -0.112 -0.213609" rpy="3.14159 -0 0"/>
        <parent link="Body_RSM_EL"/>
        <child link="Frame_SCRMI"/>
    </joint>
    <joint name="Joint_for_Frame_SCLIBS" type="fixed">
        <origin xyz="-0.062479 -0.112 -0.213609" rpy="3.14159 -0 0"/>
        <parent link="Body_RSM_EL"/>
        <child link="Frame_SCLIBS"/>
    </joint>
    <joint name="Joint_for_Frame_SCIR" type="fixed">
        <origin xyz="-0.062479 -0.112 -0.213609" rpy="3.14159 -0 0"/>
        <parent link="Body_RSM_EL"/>
        <child link="Frame_SCIR"/>
    </joint>
    <joint name="Joint_for_Frame_MCL" type="fixed">
        <origin xyz="-0.085135 -0.126634 -0.065127" rpy="0 -0 0.0219954"/>
        <parent link="Body_RSM_EL"/>
        <child link="Frame_MCL"/>
    </joint>
    <joint name="Joint_for_Frame_MCR" type="fixed">
        <origin xyz="-0.085134 0.121506 -0.065128" rpy="0 -0 -0.0220028"/>
        <parent link="Body_RSM_EL"/>
        <child link="Frame_MCR"/>
    </joint>
    <joint name="Joint_for_Frame_NCL" type="fixed">
        <origin xyz="0.080595 -0.214392 -0.057109" rpy="1.57079 1.57079 1.57079"/>
        <parent link="Body_RSM_EL"/>
        <child link="Frame_NCL"/>
    </joint>
    <joint name="Joint_for_Frame_NCR" type="fixed">
        <origin xyz="0.080595 0.209607 -0.057111" rpy="1.57079 1.57079 1.57079"/>
        <parent link="Body_RSM_EL"/>
        <child link="Frame_NCR"/>
    </joint>
    <joint name="Joint_for_Frame_NCL_FOV" type="fixed">
        <origin xyz="0.143595 -0.214392 -0.057109" rpy="1.57079 1.57079 1.57079"/>
        <parent link="Body_RSM_EL"/>
        <child link="Frame_NCL_FOV"/>
    </joint>
    <joint name="Joint_for_Frame_NCR_FOV" type="fixed">
        <origin xyz="0.143595 0.209607 -0.057111" rpy="1.57079 1.57079 1.57079"/>
        <parent link="Body_RSM_EL"/>
        <child link="Frame_NCR_FOV"/>
    </joint>
    <joint name="Joint_for_Frame_ROCKER_L" type="fixed">
        <origin xyz="0 0 0" rpy="-1.5708 -0 0"/>
        <parent link="Body_RockerLeft"/>
        <child link="Frame_ROCKER_L"/>
    </joint>
    <joint name="Joint_for_Frame_ROCKER_R" type="fixed">
        <origin xyz="0 0 0" rpy="-1.5708 -0 0"/>
        <parent link="Body_RockerRight"/>
        <child link="Frame_ROCKER_R"/>
    </joint>
    <joint name="Joint_for_Frame_BOGIE_L" type="fixed">
        <origin xyz="0 0 0" rpy="-1.5708 -0 0"/>
        <parent link="Body_BogieLeft"/>
        <child link="Frame_BOGIE_L"/>
    </joint>
    <joint name="Joint_for_Frame_BOGIE_R" type="fixed">
        <origin xyz="0 0 0" rpy="-1.5708 -0 0"/>
        <parent link="Body_BogieRight"/>
        <child link="Frame_BOGIE_R"/>
    </joint>
    <joint name="Joint_for_Frame_DIFF" type="fixed">
        <origin xyz="0 0 0" rpy="0 -0 0"/>
        <parent link="Body_Differential"/>
        <child link="Frame_DIFF"/>
    </joint>
    <joint name="Joint_for_Frame_STEER_LF" type="fixed">
        <origin xyz="0 0 0" rpy="0 -0 0"/>
        <parent link="Body_SteerLeftFront"/>
        <child link="Frame_STEER_LF"/>
    </joint>
    <joint name="Joint_for_Frame_STEER_LR" type="fixed">
        <origin xyz="0 0 0" rpy="0 -0 0"/>
        <parent link="Body_SteerLeftRear"/>
        <child link="Frame_STEER_LR"/>
    </joint>
    <joint name="Joint_for_Frame_STEER_RF" type="fixed">
        <origin xyz="0 0 0" rpy="0 -0 0"/>
        <parent link="Body_SteerRightFront"/>
        <child link="Frame_STEER_RF"/>
    </joint>
    <joint name="Joint_for_Frame_STEER_RR" type="fixed">
        <origin xyz="0 0 0" rpy="0 -0 0"/>
        <parent link="Body_SteerRightRear"/>
        <child link="Frame_STEER_RR"/>
    </joint>
    <joint name="Joint_for_Frame_WHEEL_LF" type="fixed">
        <origin xyz="0 0 0" rpy="0 -0 0"/>
        <parent link="Body_WheelLeftFront"/>
        <child link="Frame_WHEEL_LF"/>
    </joint>
    <joint name="Joint_for_Frame_WHEEL_LM" type="fixed">
        <origin xyz="0 0 0" rpy="0 -0 0"/>
        <parent link="Body_WheelLeftMiddle"/>
        <child link="Frame_WHEEL_LM"/>
    </joint>
    <joint name="Joint_for_Frame_WHEEL_LR" type="fixed">
        <origin xyz="0 0 0" rpy="0 -0 0"/>
        <parent link="Body_WheelLeftRear"/>
        <child link="Frame_WHEEL_LR"/>
    </joint>
    <joint name="Joint_for_Frame_WHEEL_RF" type="fixed">
        <origin xyz="0 0 0" rpy="0 -0 0"/>
        <parent link="Body_WheelRightFront"/>
        <child link="Frame_WHEEL_RF"/>
    </joint>
    <joint name="Joint_for_Frame_WHEEL_RM" type="fixed">
        <origin xyz="0 0 0" rpy="0 -0 0"/>
        <parent link="Body_WheelRightMiddle"/>
        <child link="Frame_WHEEL_RM"/>
    </joint>
    <joint name="Joint_for_Frame_WHEEL_RR" type="fixed">
        <origin xyz="0 0 0" rpy="0 -0 0"/>
        <parent link="Body_WheelRightRear"/>
        <child link="Frame_WHEEL_RR"/>
    </joint>
    <joint name="Joint_for_Frame_RIMUA" type="fixed">
        <origin xyz="0.310906 -0.441586 -1.04738" rpy="0 0 -1.5708"/>
        <parent link="Body_Chassis"/>
        <child link="Frame_RIMUA"/>
    </joint>
    <joint name="Joint_for_Frame_RIMUB" type="fixed">
        <origin xyz="0.403906 -0.441586 -1.04738" rpy="0 0 -1.5708"/>
        <parent link="Body_Chassis"/>
        <child link="Frame_RIMUB"/>
    </joint>
    <joint name="Joint_for_Frame_RIMFAX" type="fixed">
        <origin xyz="-0.79478 0 -0.71724" rpy="-0.686834 -5.55112e-17 1.5708"/>
        <parent link="Body_Chassis"/>
        <child link="Frame_RIMFAX"/>
    </joint>
    <joint name="Joint_for_Frame_HGAS" type="fixed">
        <origin xyz="-0.36998 -0.475 -1.13288" rpy="0 -0 0.436316"/>
        <parent link="Body_Chassis"/>
        <child link="Frame_HGAS"/>
    </joint>
    <joint name="Joint_for_Frame_HGAG" type="fixed">
        <origin xyz="0 0 0" rpy="3.14159 -0 0"/>
        <parent link="Body_HGA_AZ"/>
        <child link="Frame_HGAG"/>
    </joint>
    <joint name="Joint_for_Frame_ANT" type="fixed">
        <origin xyz="0.2084 0 0" rpy="2.35619 -0 0"/>
        <parent link="Body_HGA_EL"/>
        <child link="Frame_ANT"/>
    </joint>
    <joint name="Joint_for_Frame_RA_BASE" type="fixed">
        <origin xyz="0.967871 -0.561 -0.90838" rpy="0 -0 0"/>
        <parent link="Body_Chassis"/>
        <child link="Frame_RA_BASE"/>
    </joint>
    <joint name="Joint_for_Frame_RA1" type="fixed">
        <origin xyz="0 0 0" rpy="0 -0 0"/>
        <parent link="Body_RA_Link1"/>
        <child link="Frame_RA1"/>
    </joint>
    <joint name="Joint_for_Frame_RA2" type="fixed">
        <origin xyz="0 0 0" rpy="1.5708 -0 0"/>
        <parent link="Body_RA_Link2"/>
        <child link="Frame_RA2"/>
    </joint>
    <joint name="Joint_for_Frame_RA3" type="fixed">
        <origin xyz="0 0 0" rpy="1.5708 -0 0"/>
        <parent link="Body_RA_Link3"/>
        <child link="Frame_RA3"/>
    </joint>
    <joint name="Joint_for_Frame_RA4" type="fixed">
        <origin xyz="0 0 0" rpy="1.5708 -0 0"/>
        <parent link="Body_RA_Link4"/>
        <child link="Frame_RA4"/>
    </joint>
    <joint name="Joint_for_Frame_RA5" type="fixed">
        <origin xyz="0 0 0" rpy="0 -0 0"/>
        <parent link="Body_RA_Link5"/>
        <child link="Frame_RA5"/>
    </joint>
    <joint name="Joint_for_Frame_RA6" type="fixed">
        <origin xyz="0 0 -0.208" rpy="0 -0 0"/>
        <parent link="Body_RA_Link5"/>
        <child link="Frame_RA6"/>
    </joint>
    <joint name="Joint_for_Frame_TURRET" type="fixed">
        <origin xyz="0 0 -0.3285" rpy="0 -0 0"/>
        <parent link="Body_RA_Link5"/>
        <child link="Frame_TURRET"/>
    </joint>
    <joint name="Joint_for_Frame_DOCKING_POST" type="fixed">
        <origin xyz="0.29715 0 -0.3285" rpy="0 -0 0"/>
        <parent link="Body_RA_Link5"/>
        <child link="Frame_DOCKING_POST"/>
    </joint>
    <joint name="Joint_for_Frame_DRILL" type="fixed">
        <origin xyz="0.373 0 -0.3285" rpy="0 -0 0"/>
        <parent link="Body_RA_Link5"/>
        <child link="Frame_DRILL"/>
    </joint>
    <joint name="Joint_for_Frame_FCS" type="fixed">
        <origin xyz="-0.37138 0 -0.2704" rpy="0 -0 3.14159"/>
        <parent link="Body_RA_Link5"/>
        <child link="Frame_FCS"/>
    </joint>
    <joint name="Joint_for_Frame_GDRT" type="fixed">
        <origin xyz="-0.283436 0.237831 -0.2625" rpy="0 -0 2.44346"/>
        <parent link="Body_RA_Link5"/>
        <child link="Frame_GDRT"/>
    </joint>
    <joint name="Joint_for_Frame_PIXL" type="fixed">
        <origin xyz="0 0.3577 -0.3385" rpy="0 -0 1.5708"/>
        <parent link="Body_RA_Link5"/>
        <child link="Frame_PIXL"/>
    </joint>
    <joint name="Joint_for_Frame_SHERLOC" type="fixed">
        <origin xyz="0.143585 -0.305411 -0.292126" rpy="0 -0 -1.22173"/>
    </joint>
    <joint name="Joint_for_Frame_WATSON" type="fixed">
    </joint>
    <joint name="Joint_for_Frame_CAL_MC1" type="fixed">
    </joint>
    <joint name="Joint_for_Frame_CAL_MC2" type="fixed">
    </joint>
    <joint name="Joint_for_Frame_CAL_SC" type="fixed">
    </joint>
    <joint name="Joint_for_Frame_CAL_PIXL" type="fixed">
    </joint>
    <joint name="Joint_for_Frame_CAL_SHERLOC" type="fixed">
    </joint>
</robot>